Workbook

Sheet Read me
A1: Golden-set adjudication
A2: For the person resolving disagreements between the two annotators (SPEC §12.4: "two annotators with disagreements resolved").
A4: 1. Open each annotator's returned file, select their whole Labels tab (Ctrl+A), copy, and paste into cell A1 of 'Annotator A' / 'Annotator B' here.
A5: 2. The Compare tab lines up A, B and the original draft label for every field. Rows where A and B differ are shaded.
A6: 3. For each shaded row, decide and type the final label in the yellow 'Agreed' column. Where A and B agree, 'Agreed' may be left blank — the agreed value is used.
A7: 4. Use cases are free text, so they are never auto-compared: read both and write the agreed list.
A8: 5. Send this file back. The agreed labels replace the draft groundTruth blocks in tests/evals/cases.ts.
A10: The 'Draft' column is the single-author first pass already in the code. It is shown only here, never to the annotators, so it could not bias their reads.
A11: The Key tab maps each L-ID to its case in the code and its SPEC group. Annotators never saw the groups.

Sheet Compare
A1: ID | B1: SPEC group | C1: Field | D1: Draft (code today) | E1: Annotator A | F1: Annotator B | G1: A vs B | H1: Agreed | I1: Final label | K1: Rows where A and B differ: | L1: =COUNTIF(G2:G801,"DIFFER")
A2: L01 | B2: near-duplicate | C2: Use cases | D2: single status view showing current approver and elapsed time | E2: =IFERROR(INDEX('Annotator A'!$C$5:$C$44,MATCH($A2,'Annotator A'!$A$5:$A$44,0))&"","") | F2: =IFERROR(INDEX('Annotator B'!$C$5:$C$44,MATCH($A2,'Annotator B'!$A$5:$A$44,0))&"","") | G2: read both | I2: =IF(H2<>"",H2,"") | K2: Differing rows still without an agreed label: | L2: =COUNTIFS(G2:G801,"DIFFER",H2:H801,"")
A3: L01 | B3: near-duplicate | C3: Value — Business impact | E3: =IFERROR(INDEX('Annotator A'!$D$5:$D$44,MATCH($A3,'Annotator A'!$A$5:$A$44,0))&"","") | F3: =IFERROR(INDEX('Annotator B'!$D$5:$D$44,MATCH($A3,'Annotator B'!$A$5:$A$44,0))&"","") | G3: =IF(AND(E3="",F3=""),"",IF(E3=F3,"agree","DIFFER")) | I3: =IF(H3<>"",H3,IF(G3="agree",E3,""))
A4: L01 | B4: near-duplicate | C4: Value — Productivity | E4: =IFERROR(INDEX('Annotator A'!$E$5:$E$44,MATCH($A4,'Annotator A'!$A$5:$A$44,0))&"","") | F4: =IFERROR(INDEX('Annotator B'!$E$5:$E$44,MATCH($A4,'Annotator B'!$A$5:$A$44,0))&"","") | G4: =IF(AND(E4="",F4=""),"",IF(E4=F4,"agree","DIFFER")) | I4: =IF(H4<>"",H4,IF(G4="agree",E4,""))
A5: L01 | B5: near-duplicate | C5: Value — Cost reduction | E5: =IFERROR(INDEX('Annotator A'!$F$5:$F$44,MATCH($A5,'Annotator A'!$A$5:$A$44,0))&"","") | F5: =IFERROR(INDEX('Annotator B'!$F$5:$F$44,MATCH($A5,'Annotator B'!$A$5:$A$44,0))&"","") | G5: =IF(AND(E5="",F5=""),"",IF(E5=F5,"agree","DIFFER")) | I5: =IF(H5<>"",H5,IF(G5="agree",E5,""))
A6: L01 | B6: near-duplicate | C6: Value — Revenue | E6: =IFERROR(INDEX('Annotator A'!$G$5:$G$44,MATCH($A6,'Annotator A'!$A$5:$A$44,0))&"","") | F6: =IFERROR(INDEX('Annotator B'!$G$5:$G$44,MATCH($A6,'Annotator B'!$A$5:$A$44,0))&"","") | G6: =IF(AND(E6="",F6=""),"",IF(E6=F6,"agree","DIFFER")) | I6: =IF(H6<>"",H6,IF(G6="agree",E6,""))
A7: L01 | B7: near-duplicate | C7: Value — Employee experience | E7: =IFERROR(INDEX('Annotator A'!$H$5:$H$44,MATCH($A7,'Annotator A'!$A$5:$A$44,0))&"","") | F7: =IFERROR(INDEX('Annotator B'!$H$5:$H$44,MATCH($A7,'Annotator B'!$A$5:$A$44,0))&"","") | G7: =IF(AND(E7="",F7=""),"",IF(E7=F7,"agree","DIFFER")) | I7: =IF(H7<>"",H7,IF(G7="agree",E7,""))
A8: L01 | B8: near-duplicate | C8: Value — Customer impact | E8: =IFERROR(INDEX('Annotator A'!$I$5:$I$44,MATCH($A8,'Annotator A'!$A$5:$A$44,0))&"","") | F8: =IFERROR(INDEX('Annotator B'!$I$5:$I$44,MATCH($A8,'Annotator B'!$A$5:$A$44,0))&"","") | G8: =IF(AND(E8="",F8=""),"",IF(E8=F8,"agree","DIFFER")) | I8: =IF(H8<>"",H8,IF(G8="agree",E8,""))
A9: L01 | B9: near-duplicate | C9: Value — Operational | D9: Moderate | E9: =IFERROR(INDEX('Annotator A'!$J$5:$J$44,MATCH($A9,'Annotator A'!$A$5:$A$44,0))&"","") | F9: =IFERROR(INDEX('Annotator B'!$J$5:$J$44,MATCH($A9,'Annotator B'!$A$5:$A$44,0))&"","") | G9: =IF(AND(E9="",F9=""),"",IF(E9=F9,"agree","DIFFER")) | I9: =IF(H9<>"",H9,IF(G9="agree",E9,""))
A10: L01 | B10: near-duplicate | C10: Value — Problem severity | E10: =IFERROR(INDEX('Annotator A'!$K$5:$K$44,MATCH($A10,'Annotator A'!$A$5:$A$44,0))&"","") | F10: =IFERROR(INDEX('Annotator B'!$K$5:$K$44,MATCH($A10,'Annotator B'!$A$5:$A$44,0))&"","") | G10: =IF(AND(E10="",F10=""),"",IF(E10=F10,"agree","DIFFER")) | I10: =IF(H10<>"",H10,IF(G10="agree",E10,""))
A11: L01 | B11: near-duplicate | C11: Value — Problem frequency | D11: High | E11: =IFERROR(INDEX('Annotator A'!$L$5:$L$44,MATCH($A11,'Annotator A'!$A$5:$A$44,0))&"","") | F11: =IFERROR(INDEX('Annotator B'!$L$5:$L$44,MATCH($A11,'Annotator B'!$A$5:$A$44,0))&"","") | G11: =IF(AND(E11="",F11=""),"",IF(E11=F11,"agree","DIFFER")) | I11: =IF(H11<>"",H11,IF(G11="agree",E11,""))
A12: L01 | B12: near-duplicate | C12: Feasibility status | D12: FEASIBLE_WITH_CONDITIONS | E12: =IFERROR(INDEX('Annotator A'!$M$5:$M$44,MATCH($A12,'Annotator A'!$A$5:$A$44,0))&"","") | F12: =IFERROR(INDEX('Annotator B'!$M$5:$M$44,MATCH($A12,'Annotator B'!$A$5:$A$44,0))&"","") | G12: =IF(AND(E12="",F12=""),"",IF(E12=F12,"agree","DIFFER")) | I12: =IF(H12<>"",H12,IF(G12="agree",E12,""))
A13: L01 | B13: near-duplicate | C13: Risk — Technical | E13: =IFERROR(INDEX('Annotator A'!$N$5:$N$44,MATCH($A13,'Annotator A'!$A$5:$A$44,0))&"","") | F13: =IFERROR(INDEX('Annotator B'!$N$5:$N$44,MATCH($A13,'Annotator B'!$A$5:$A$44,0))&"","") | G13: =IF(AND(E13="",F13=""),"",IF(E13=F13,"agree","DIFFER")) | I13: =IF(H13<>"",H13,IF(G13="agree",E13,""))
A14: L01 | B14: near-duplicate | C14: Risk — Security | E14: =IFERROR(INDEX('Annotator A'!$O$5:$O$44,MATCH($A14,'Annotator A'!$A$5:$A$44,0))&"","") | F14: =IFERROR(INDEX('Annotator B'!$O$5:$O$44,MATCH($A14,'Annotator B'!$A$5:$A$44,0))&"","") | G14: =IF(AND(E14="",F14=""),"",IF(E14=F14,"agree","DIFFER")) | I14: =IF(H14<>"",H14,IF(G14="agree",E14,""))
A15: L01 | B15: near-duplicate | C15: Risk — Privacy | E15: =IFERROR(INDEX('Annotator A'!$P$5:$P$44,MATCH($A15,'Annotator A'!$A$5:$A$44,0))&"","") | F15: =IFERROR(INDEX('Annotator B'!$P$5:$P$44,MATCH($A15,'Annotator B'!$A$5:$A$44,0))&"","") | G15: =IF(AND(E15="",F15=""),"",IF(E15=F15,"agree","DIFFER")) | I15: =IF(H15<>"",H15,IF(G15="agree",E15,""))
A16: L01 | B16: near-duplicate | C16: Risk — Compliance | E16: =IFERROR(INDEX('Annotator A'!$Q$5:$Q$44,MATCH($A16,'Annotator A'!$A$5:$A$44,0))&"","") | F16: =IFERROR(INDEX('Annotator B'!$Q$5:$Q$44,MATCH($A16,'Annotator B'!$A$5:$A$44,0))&"","") | G16: =IF(AND(E16="",F16=""),"",IF(E16=F16,"agree","DIFFER")) | I16: =IF(H16<>"",H16,IF(G16="agree",E16,""))
A17: L01 | B17: near-duplicate | C17: Risk — Financial | E17: =IFERROR(INDEX('Annotator A'!$R$5:$R$44,MATCH($A17,'Annotator A'!$A$5:$A$44,0))&"","") | F17: =IFERROR(INDEX('Annotator B'!$R$5:$R$44,MATCH($A17,'Annotator B'!$A$5:$A$44,0))&"","") | G17: =IF(AND(E17="",F17=""),"",IF(E17=F17,"agree","DIFFER")) | I17: =IF(H17<>"",H17,IF(G17="agree",E17,""))
A18: L01 | B18: near-duplicate | C18: Risk — Operational | E18: =IFERROR(INDEX('Annotator A'!$S$5:$S$44,MATCH($A18,'Annotator A'!$A$5:$A$44,0))&"","") | F18: =IFERROR(INDEX('Annotator B'!$S$5:$S$44,MATCH($A18,'Annotator B'!$A$5:$A$44,0))&"","") | G18: =IF(AND(E18="",F18=""),"",IF(E18=F18,"agree","DIFFER")) | I18: =IF(H18<>"",H18,IF(G18="agree",E18,""))
A19: L01 | B19: near-duplicate | C19: Risk — Adoption | E19: =IFERROR(INDEX('Annotator A'!$T$5:$T$44,MATCH($A19,'Annotator A'!$A$5:$A$44,0))&"","") | F19: =IFERROR(INDEX('Annotator B'!$T$5:$T$44,MATCH($A19,'Annotator B'!$A$5:$A$44,0))&"","") | G19: =IF(AND(E19="",F19=""),"",IF(E19=F19,"agree","DIFFER")) | I19: =IF(H19<>"",H19,IF(G19="agree",E19,""))
A20: L01 | B20: near-duplicate | C20: Risk — Data | E20: =IFERROR(INDEX('Annotator A'!$U$5:$U$44,MATCH($A20,'Annotator A'!$A$5:$A$44,0))&"","") | F20: =IFERROR(INDEX('Annotator B'!$U$5:$U$44,MATCH($A20,'Annotator B'!$A$5:$A$44,0))&"","") | G20: =IF(AND(E20="",F20=""),"",IF(E20=F20,"agree","DIFFER")) | I20: =IF(H20<>"",H20,IF(G20="agree",E20,""))
A21: L01 | B21: near-duplicate | C21: Risk — Vendor | E21: =IFERROR(INDEX('Annotator A'!$V$5:$V$44,MATCH($A21,'Annotator A'!$A$5:$A$44,0))&"","") | F21: =IFERROR(INDEX('Annotator B'!$V$5:$V$44,MATCH($A21,'Annotator B'!$A$5:$A$44,0))&"","") | G21: =IF(AND(E21="",F21=""),"",IF(E21=F21,"agree","DIFFER")) | I21: =IF(H21<>"",H21,IF(G21="agree",E21,""))
A22: L02 | B22: infeasible | C22: Use cases | E22: =IFERROR(INDEX('Annotator A'!$C$5:$C$44,MATCH($A22,'Annotator A'!$A$5:$A$44,0))&"","") | F22: =IFERROR(INDEX('Annotator B'!$C$5:$C$44,MATCH($A22,'Annotator B'!$A$5:$A$44,0))&"","") | G22: read both | I22: =IF(H22<>"",H22,"")
A23: L02 | B23: infeasible | C23: Value — Business impact | E23: =IFERROR(INDEX('Annotator A'!$D$5:$D$44,MATCH($A23,'Annotator A'!$A$5:$A$44,0))&"","") | F23: =IFERROR(INDEX('Annotator B'!$D$5:$D$44,MATCH($A23,'Annotator B'!$A$5:$A$44,0))&"","") | G23: =IF(AND(E23="",F23=""),"",IF(E23=F23,"agree","DIFFER")) | I23: =IF(H23<>"",H23,IF(G23="agree",E23,""))
A24: L02 | B24: infeasible | C24: Value — Productivity | E24: =IFERROR(INDEX('Annotator A'!$E$5:$E$44,MATCH($A24,'Annotator A'!$A$5:$A$44,0))&"","") | F24: =IFERROR(INDEX('Annotator B'!$E$5:$E$44,MATCH($A24,'Annotator B'!$A$5:$A$44,0))&"","") | G24: =IF(AND(E24="",F24=""),"",IF(E24=F24,"agree","DIFFER")) | I24: =IF(H24<>"",H24,IF(G24="agree",E24,""))
A25: L02 | B25: infeasible | C25: Value — Cost reduction | E25: =IFERROR(INDEX('Annotator A'!$F$5:$F$44,MATCH($A25,'Annotator A'!$A$5:$A$44,0))&"","") | F25: =IFERROR(INDEX('Annotator B'!$F$5:$F$44,MATCH($A25,'Annotator B'!$A$5:$A$44,0))&"","") | G25: =IF(AND(E25="",F25=""),"",IF(E25=F25,"agree","DIFFER")) | I25: =IF(H25<>"",H25,IF(G25="agree",E25,""))
A26: L02 | B26: infeasible | C26: Value — Revenue | E26: =IFERROR(INDEX('Annotator A'!$G$5:$G$44,MATCH($A26,'Annotator A'!$A$5:$A$44,0))&"","") | F26: =IFERROR(INDEX('Annotator B'!$G$5:$G$44,MATCH($A26,'Annotator B'!$A$5:$A$44,0))&"","") | G26: =IF(AND(E26="",F26=""),"",IF(E26=F26,"agree","DIFFER")) | I26: =IF(H26<>"",H26,IF(G26="agree",E26,""))
A27: L02 | B27: infeasible | C27: Value — Employee experience | E27: =IFERROR(INDEX('Annotator A'!$H$5:$H$44,MATCH($A27,'Annotator A'!$A$5:$A$44,0))&"","") | F27: =IFERROR(INDEX('Annotator B'!$H$5:$H$44,MATCH($A27,'Annotator B'!$A$5:$A$44,0))&"","") | G27: =IF(AND(E27="",F27=""),"",IF(E27=F27,"agree","DIFFER")) | I27: =IF(H27<>"",H27,IF(G27="agree",E27,""))
A28: L02 | B28: infeasible | C28: Value — Customer impact | E28: =IFERROR(INDEX('Annotator A'!$I$5:$I$44,MATCH($A28,'Annotator A'!$A$5:$A$44,0))&"","") | F28: =IFERROR(INDEX('Annotator B'!$I$5:$I$44,MATCH($A28,'Annotator B'!$A$5:$A$44,0))&"","") | G28: =IF(AND(E28="",F28=""),"",IF(E28=F28,"agree","DIFFER")) | I28: =IF(H28<>"",H28,IF(G28="agree",E28,""))
A29: L02 | B29: infeasible | C29: Value — Operational | E29: =IFERROR(INDEX('Annotator A'!$J$5:$J$44,MATCH($A29,'Annotator A'!$A$5:$A$44,0))&"","") | F29: =IFERROR(INDEX('Annotator B'!$J$5:$J$44,MATCH($A29,'Annotator B'!$A$5:$A$44,0))&"","") | G29: =IF(AND(E29="",F29=""),"",IF(E29=F29,"agree","DIFFER")) | I29: =IF(H29<>"",H29,IF(G29="agree",E29,""))
A30: L02 | B30: infeasible | C30: Value — Problem severity | E30: =IFERROR(INDEX('Annotator A'!$K$5:$K$44,MATCH($A30,'Annotator A'!$A$5:$A$44,0))&"","") | F30: =IFERROR(INDEX('Annotator B'!$K$5:$K$44,MATCH($A30,'Annotator B'!$A$5:$A$44,0))&"","") | G30: =IF(AND(E30="",F30=""),"",IF(E30=F30,"agree","DIFFER")) | I30: =IF(H30<>"",H30,IF(G30="agree",E30,""))
A31: L02 | B31: infeasible | C31: Value — Problem frequency | E31: =IFERROR(INDEX('Annotator A'!$L$5:$L$44,MATCH($A31,'Annotator A'!$A$5:$A$44,0))&"","") | F31: =IFERROR(INDEX('Annotator B'!$L$5:$L$44,MATCH($A31,'Annotator B'!$A$5:$A$44,0))&"","") | G31: =IF(AND(E31="",F31=""),"",IF(E31=F31,"agree","DIFFER")) | I31: =IF(H31<>"",H31,IF(G31="agree",E31,""))
A32: L02 | B32: infeasible | C32: Feasibility status | D32: NOT_CURRENTLY_FEASIBLE | E32: =IFERROR(INDEX('Annotator A'!$M$5:$M$44,MATCH($A32,'Annotator A'!$A$5:$A$44,0))&"","") | F32: =IFERROR(INDEX('Annotator B'!$M$5:$M$44,MATCH($A32,'Annotator B'!$A$5:$A$44,0))&"","") | G32: =IF(AND(E32="",F32=""),"",IF(E32=F32,"agree","DIFFER")) | I32: =IF(H32<>"",H32,IF(G32="agree",E32,""))
A33: L02 | B33: infeasible | C33: Risk — Technical | E33: =IFERROR(INDEX('Annotator A'!$N$5:$N$44,MATCH($A33,'Annotator A'!$A$5:$A$44,0))&"","") | F33: =IFERROR(INDEX('Annotator B'!$N$5:$N$44,MATCH($A33,'Annotator B'!$A$5:$A$44,0))&"","") | G33: =IF(AND(E33="",F33=""),"",IF(E33=F33,"agree","DIFFER")) | I33: =IF(H33<>"",H33,IF(G33="agree",E33,""))
A34: L02 | B34: infeasible | C34: Risk — Security | E34: =IFERROR(INDEX('Annotator A'!$O$5:$O$44,MATCH($A34,'Annotator A'!$A$5:$A$44,0))&"","") | F34: =IFERROR(INDEX('Annotator B'!$O$5:$O$44,MATCH($A34,'Annotator B'!$A$5:$A$44,0))&"","") | G34: =IF(AND(E34="",F34=""),"",IF(E34=F34,"agree","DIFFER")) | I34: =IF(H34<>"",H34,IF(G34="agree",E34,""))
A35: L02 | B35: infeasible | C35: Risk — Privacy | E35: =IFERROR(INDEX('Annotator A'!$P$5:$P$44,MATCH($A35,'Annotator A'!$A$5:$A$44,0))&"","") | F35: =IFERROR(INDEX('Annotator B'!$P$5:$P$44,MATCH($A35,'Annotator B'!$A$5:$A$44,0))&"","") | G35: =IF(AND(E35="",F35=""),"",IF(E35=F35,"agree","DIFFER")) | I35: =IF(H35<>"",H35,IF(G35="agree",E35,""))
A36: L02 | B36: infeasible | C36: Risk — Compliance | D36: Yes | E36: =IFERROR(INDEX('Annotator A'!$Q$5:$Q$44,MATCH($A36,'Annotator A'!$A$5:$A$44,0))&"","") | F36: =IFERROR(INDEX('Annotator B'!$Q$5:$Q$44,MATCH($A36,'Annotator B'!$A$5:$A$44,0))&"","") | G36: =IF(AND(E36="",F36=""),"",IF(E36=F36,"agree","DIFFER")) | I36: =IF(H36<>"",H36,IF(G36="agree",E36,""))
A37: L02 | B37: infeasible | C37: Risk — Financial | D37: Yes | E37: =IFERROR(INDEX('Annotator A'!$R$5:$R$44,MATCH($A37,'Annotator A'!$A$5:$A$44,0))&"","") | F37: =IFERROR(INDEX('Annotator B'!$R$5:$R$44,MATCH($A37,'Annotator B'!$A$5:$A$44,0))&"","") | G37: =IF(AND(E37="",F37=""),"",IF(E37=F37,"agree","DIFFER")) | I37: =IF(H37<>"",H37,IF(G37="agree",E37,""))
A38: L02 | B38: infeasible | C38: Risk — Operational | E38: =IFERROR(INDEX('Annotator A'!$S$5:$S$44,MATCH($A38,'Annotator A'!$A$5:$A$44,0))&"","") | F38: =IFERROR(INDEX('Annotator B'!$S$5:$S$44,MATCH($A38,'Annotator B'!$A$5:$A$44,0))&"","") | G38: =IF(AND(E38="",F38=""),"",IF(E38=F38,"agree","DIFFER")) | I38: =IF(H38<>"",H38,IF(G38="agree",E38,""))
A39: L02 | B39: infeasible | C39: Risk — Adoption | E39: =IFERROR(INDEX('Annotator A'!$T$5:$T$44,MATCH($A39,'Annotator A'!$A$5:$A$44,0))&"","") | F39: =IFERROR(INDEX('Annotator B'!$T$5:$T$44,MATCH($A39,'Annotator B'!$A$5:$A$44,0))&"","") | G39: =IF(AND(E39="",F39=""),"",IF(E39=F39,"agree","DIFFER")) | I39: =IF(H39<>"",H39,IF(G39="agree",E39,""))
A40: L02 | B40: infeasible | C40: Risk — Data | E40: =IFERROR(INDEX('Annotator A'!$U$5:$U$44,MATCH($A40,'Annotator A'!$A$5:$A$44,0))&"","") | F40: =IFERROR(INDEX('Annotator B'!$U$5:$U$44,MATCH($A40,'Annotator B'!$A$5:$A$44,0))&"","") | G40: =IF(AND(E40="",F40=""),"",IF(E40=F40,"agree","DIFFER")) | I40: =IF(H40<>"",H40,IF(G40="agree",E40,""))
...

Sheet Lists
A1: Band | B1: Feasibility | C1: Risk present
A2: Negligible | B2: HIGHLY_FEASIBLE | C2: Yes
A3: Low | B3: FEASIBLE_WITH_CONDITIONS
A4: Moderate | B4: REQUIRES_INVESTIGATION
A5: High | B5: NOT_CURRENTLY_FEASIBLE
A6: Very high

Sheet Annotator A
A1: Annotator name: | D1: Ideas with a feasibility status entered: | H1: =COUNTA(M5:M44)&" of 40"
A2: Yellow cells are yours to fill in. Leave any cell blank if you cannot judge it from the text — blank is not wrong.
A4: ID | B4: Idea title (for reference) | C4: Use cases — one per line | D4: Value — Business impact | E4: Value — Productivity | F4: Value — Cost reduction | G4: Value — Revenue | H4: Value — Employee experience | I4: Value — Customer impact | J4: Value — Operational | K4: Value — Problem severity | L4: Value — Problem frequency | M4: Feasibility status | N4: Risk — Technical | O4: Risk — Security | P4: Risk — Privacy | Q4: Risk — Compliance | R4: Risk — Financial | S4: Risk — Operational | T4: Risk — Adoption | U4: Risk — Data | V4: Risk — Vendor | W4: Notes / doubts (optional)
A5: L01 | B5: No one can see where an approval is stuck
A6: L02 | B6: Auto-approve any expense report without manager review
A7: L03 | B7: Speed up approvals
A8: L04 | B8: Fix our messy file storage
A9: L05 | B9: Better reporting
A10: L06 | B10: Improve data quality
A11: L07 | B11: Facial-recognition-based attendance tracking
A12: L08 | B12: New starters wait too long for a laptop
A13: L09 | B13: Faster laptop provisioning for new hires
A14: L10 | B14: Clean up the shared drive folder structure
A15: L11 | B15: Self-service password reset portal
A16: L12 | B16: Fewer meetings
... A44: L40 | B44: Automated expense approval reminders

Sheet Annotator B
A1: Annotator name: | D1: Ideas with a feasibility status entered: | H1: =COUNTA(M5:M44)&" of 40"
A2: Yellow cells are yours to fill in. Leave any cell blank if you cannot judge it from the text — blank is not wrong.
A4: ID | B4: Idea title (for reference) | C4: Use cases — one per line | D4: Value — Business impact | E4: Value — Productivity | F4: Value — Cost reduction | G4: Value — Revenue | H4: Value — Employee experience | I4: Value — Customer impact | J4: Value — Operational | K4: Value — Problem severity | L4: Value — Problem frequency | M4: Feasibility status | N4: Risk — Technical | O4: Risk — Security | P4: Risk — Privacy | Q4: Risk — Compliance | R4: Risk — Financial | S4: Risk — Operational | T4: Risk — Adoption | U4: Risk — Data | V4: Risk — Vendor | W4: Notes / doubts (optional)
A5: L01 | B5: No one can see where an approval is stuck
A6: L02 | B6: Auto-approve any expense report without manager review
A7: L03 | B7: Speed up approvals
A8: L04 | B8: Fix our messy file storage
A9: L05 | B9: Better reporting
A10: L06 | B10: Improve data quality
A11: L07 | B11: Facial-recognition-based attendance tracking
A12: L08 | B12: New starters wait too long for a laptop
A13: L09 | B13: Faster laptop provisioning for new hires
A14: L10 | B14: Clean up the shared drive folder structure
A15: L11 | B15: Self-service password reset portal
A16: L12 | B16: Fewer meetings
... A44: L40 | B44: Automated expense approval reminders

Sheet Key
A1: ID | B1: Case name in tests/evals/cases.ts | C1: SPEC group | D1: Title
A2: L01 | B2: near-duplicate (2 of 2) — no one can see where an approval is stuck | C2: near-duplicate | D2: No one can see where an approval is stuck
A3: L02 | B3: infeasible — auto-approving expenses with no review, against financial controls | C3: infeasible | D3: Auto-approve any expense report without manager review
A4: L03 | B4: vague — speed up approvals, unspecified | C4: vague | D4: Speed up approvals
A5: L04 | B5: near-duplicate (2 of 2) — same problem, phrased independently | C5: near-duplicate | D5: Fix our messy file storage
A6: L05 | B6: vague — better reporting, no specifics | C6: vague | D6: Better reporting
A7: L06 | B7: vague — improve data quality, unspecified | C7: vague | D7: Improve data quality
A8: L07 | B8: infeasible — biometric attendance tracking against a stated policy constraint | C8: infeasible | D8: Facial-recognition-based attendance tracking
A9: L08 | B9: near-duplicate (2 of 2) — new starters wait too long for a laptop | C9: near-duplicate | D9: New starters wait too long for a laptop
A10: L09 | B10: near-duplicate (1 of 2) — faster laptop provisioning for new hires | C10: near-duplicate | D10: Faster laptop provisioning for new hires
A11: L10 | B11: near-duplicate (1 of 2) — shared drive folder cleanup | C11: near-duplicate | D11: Clean up the shared drive folder structure
A12: L11 | B12: well-specified — self-service password reset | C12: strong | D12: Self-service password reset portal
... A41: L40 | B41: well-specified — expense approval automation | C41: strong | D41: Automated expense approval reminders
